============================= test session starts =============================
platform win32 -- Python 3.10.11, pytest-8.3.4, pluggy-1.5.0 -- E:\Alfurquan\Self-Learning\Python\subprocess-vs-psutils\venv\Scripts\python.exe
cachedir: .pytest_cache
rootdir: E:\Alfurquan\Self-Learning\Python\subprocess-vs-psutils
collecting ... collected 1 item

test/test-one/test_one.py::test_one Setting up signal handler
Pytest id:  60384
Received termination signal: 2
Cleaning up resources...

INTERNALERROR> Traceback (most recent call last):
INTERNALERROR>   File "E:\Alfurquan\Self-Learning\Python\subprocess-vs-psutils\venv\lib\site-packages\_pytest\main.py", line 283, in wrap_session
INTERNALERROR>     session.exitstatus = doit(config, session) or 0
INTERNALERROR>   File "E:\Alfurquan\Self-Learning\Python\subprocess-vs-psutils\venv\lib\site-packages\_pytest\main.py", line 337, in _main
INTERNALERROR>     config.hook.pytest_runtestloop(session=session)
INTERNALERROR>   File "E:\Alfurquan\Self-Learning\Python\subprocess-vs-psutils\venv\lib\site-packages\pluggy\_hooks.py", line 513, in __call__
INTERNALERROR>     return self._hookexec(self.name, self._hookimpls.copy(), kwargs, firstresult)
INTERNALERROR>   File "E:\Alfurquan\Self-Learning\Python\subprocess-vs-psutils\venv\lib\site-packages\pluggy\_manager.py", line 120, in _hookexec
INTERNALERROR>     return self._inner_hookexec(hook_name, methods, kwargs, firstresult)
INTERNALERROR>   File "E:\Alfurquan\Self-Learning\Python\subprocess-vs-psutils\venv\lib\site-packages\pluggy\_callers.py", line 139, in _multicall
INTERNALERROR>     raise exception.with_traceback(exception.__traceback__)
INTERNALERROR>   File "E:\Alfurquan\Self-Learning\Python\subprocess-vs-psutils\venv\lib\site-packages\pluggy\_callers.py", line 122, in _multicall
INTERNALERROR>     teardown.throw(exception)  # type: ignore[union-attr]
INTERNALERROR>   File "E:\Alfurquan\Self-Learning\Python\subprocess-vs-psutils\venv\lib\site-packages\_pytest\logging.py", line 803, in pytest_runtestloop
INTERNALERROR>     return (yield)  # Run all the tests.
INTERNALERROR>   File "E:\Alfurquan\Self-Learning\Python\subprocess-vs-psutils\venv\lib\site-packages\pluggy\_callers.py", line 122, in _multicall
INTERNALERROR>     teardown.throw(exception)  # type: ignore[union-attr]
INTERNALERROR>   File "E:\Alfurquan\Self-Learning\Python\subprocess-vs-psutils\venv\lib\site-packages\_pytest\terminal.py", line 673, in pytest_runtestloop
INTERNALERROR>     result = yield
INTERNALERROR>   File "E:\Alfurquan\Self-Learning\Python\subprocess-vs-psutils\venv\lib\site-packages\pluggy\_callers.py", line 103, in _multicall
INTERNALERROR>     res = hook_impl.function(*args)
INTERNALERROR>   File "E:\Alfurquan\Self-Learning\Python\subprocess-vs-psutils\venv\lib\site-packages\_pytest\main.py", line 362, in pytest_runtestloop
INTERNALERROR>     item.config.hook.pytest_runtest_protocol(item=item, nextitem=nextitem)
INTERNALERROR>   File "E:\Alfurquan\Self-Learning\Python\subprocess-vs-psutils\venv\lib\site-packages\pluggy\_hooks.py", line 513, in __call__
INTERNALERROR>     return self._hookexec(self.name, self._hookimpls.copy(), kwargs, firstresult)
INTERNALERROR>   File "E:\Alfurquan\Self-Learning\Python\subprocess-vs-psutils\venv\lib\site-packages\pluggy\_manager.py", line 120, in _hookexec
INTERNALERROR>     return self._inner_hookexec(hook_name, methods, kwargs, firstresult)
INTERNALERROR>   File "E:\Alfurquan\Self-Learning\Python\subprocess-vs-psutils\venv\lib\site-packages\pluggy\_callers.py", line 139, in _multicall
INTERNALERROR>     raise exception.with_traceback(exception.__traceback__)
INTERNALERROR>   File "E:\Alfurquan\Self-Learning\Python\subprocess-vs-psutils\venv\lib\site-packages\pluggy\_callers.py", line 122, in _multicall
INTERNALERROR>     teardown.throw(exception)  # type: ignore[union-attr]
INTERNALERROR>   File "E:\Alfurquan\Self-Learning\Python\subprocess-vs-psutils\venv\lib\site-packages\_pytest\warnings.py", line 112, in pytest_runtest_protocol
INTERNALERROR>     return (yield)
INTERNALERROR>   File "E:\Alfurquan\Self-Learning\Python\subprocess-vs-psutils\venv\lib\site-packages\pluggy\_callers.py", line 122, in _multicall
INTERNALERROR>     teardown.throw(exception)  # type: ignore[union-attr]
INTERNALERROR>   File "E:\Alfurquan\Self-Learning\Python\subprocess-vs-psutils\venv\lib\site-packages\_pytest\assertion\__init__.py", line 176, in pytest_runtest_protocol
INTERNALERROR>     return (yield)
INTERNALERROR>   File "E:\Alfurquan\Self-Learning\Python\subprocess-vs-psutils\venv\lib\site-packages\pluggy\_callers.py", line 122, in _multicall
INTERNALERROR>     teardown.throw(exception)  # type: ignore[union-attr]
INTERNALERROR>   File "E:\Alfurquan\Self-Learning\Python\subprocess-vs-psutils\venv\lib\site-packages\_pytest\unittest.py", line 429, in pytest_runtest_protocol
INTERNALERROR>     res = yield
INTERNALERROR>   File "E:\Alfurquan\Self-Learning\Python\subprocess-vs-psutils\venv\lib\site-packages\pluggy\_callers.py", line 122, in _multicall
INTERNALERROR>     teardown.throw(exception)  # type: ignore[union-attr]
INTERNALERROR>   File "E:\Alfurquan\Self-Learning\Python\subprocess-vs-psutils\venv\lib\site-packages\_pytest\faulthandler.py", line 88, in pytest_runtest_protocol
INTERNALERROR>     return (yield)
INTERNALERROR>   File "E:\Alfurquan\Self-Learning\Python\subprocess-vs-psutils\venv\lib\site-packages\pluggy\_callers.py", line 103, in _multicall
INTERNALERROR>     res = hook_impl.function(*args)
INTERNALERROR>   File "E:\Alfurquan\Self-Learning\Python\subprocess-vs-psutils\venv\lib\site-packages\_pytest\runner.py", line 113, in pytest_runtest_protocol
INTERNALERROR>     runtestprotocol(item, nextitem=nextitem)
INTERNALERROR>   File "E:\Alfurquan\Self-Learning\Python\subprocess-vs-psutils\venv\lib\site-packages\_pytest\runner.py", line 132, in runtestprotocol
INTERNALERROR>     reports.append(call_and_report(item, "call", log))
INTERNALERROR>   File "E:\Alfurquan\Self-Learning\Python\subprocess-vs-psutils\venv\lib\site-packages\_pytest\runner.py", line 244, in call_and_report
INTERNALERROR>     report: TestReport = ihook.pytest_runtest_makereport(item=item, call=call)
INTERNALERROR>   File "E:\Alfurquan\Self-Learning\Python\subprocess-vs-psutils\venv\lib\site-packages\pluggy\_hooks.py", line 513, in __call__
INTERNALERROR>     return self._hookexec(self.name, self._hookimpls.copy(), kwargs, firstresult)
INTERNALERROR>   File "E:\Alfurquan\Self-Learning\Python\subprocess-vs-psutils\venv\lib\site-packages\pluggy\_manager.py", line 120, in _hookexec
INTERNALERROR>     return self._inner_hookexec(hook_name, methods, kwargs, firstresult)
INTERNALERROR>   File "E:\Alfurquan\Self-Learning\Python\subprocess-vs-psutils\venv\lib\site-packages\pluggy\_callers.py", line 139, in _multicall
INTERNALERROR>     raise exception.with_traceback(exception.__traceback__)
INTERNALERROR>   File "E:\Alfurquan\Self-Learning\Python\subprocess-vs-psutils\venv\lib\site-packages\pluggy\_callers.py", line 122, in _multicall
INTERNALERROR>     teardown.throw(exception)  # type: ignore[union-attr]
INTERNALERROR>   File "E:\Alfurquan\Self-Learning\Python\subprocess-vs-psutils\venv\lib\site-packages\_pytest\tmpdir.py", line 310, in pytest_runtest_makereport
INTERNALERROR>     rep = yield
INTERNALERROR>   File "E:\Alfurquan\Self-Learning\Python\subprocess-vs-psutils\venv\lib\site-packages\pluggy\_callers.py", line 122, in _multicall
INTERNALERROR>     teardown.throw(exception)  # type: ignore[union-attr]
INTERNALERROR>   File "E:\Alfurquan\Self-Learning\Python\subprocess-vs-psutils\venv\lib\site-packages\_pytest\skipping.py", line 269, in pytest_runtest_makereport
INTERNALERROR>     rep = yield
INTERNALERROR>   File "E:\Alfurquan\Self-Learning\Python\subprocess-vs-psutils\venv\lib\site-packages\pluggy\_callers.py", line 103, in _multicall
INTERNALERROR>     res = hook_impl.function(*args)
INTERNALERROR>   File "E:\Alfurquan\Self-Learning\Python\subprocess-vs-psutils\test\conftest.py", line 12, in pytest_runtest_makereport
INTERNALERROR>     report.longreprtext = custom_message  # Override the long failure message
INTERNALERROR> AttributeError: can't set attribute 'longreprtext'
Restoring signal handler

============================= 1 warning in 4.77s ==============================
